我接下来会问一个问题，然后提供一些参考文本，请结合我提供的参考文本回答我的问题。@$@
 好的，请提供你的问题。@$@@$@@$@
 hello@$@
 好的，我已经收到你的问题，请提供你的参考文本@$@
 Traceback (most recent call last):  File "D:\Program Files\Python\Python311\Lib\site-packages\urllib3\connection.py", line 199, in _new_conn    sock = connection.create_connection(           ^^^^^^^^^^^^^^^^^^^^^^^^^^^^^  File "D:\Program Files\Python\Python311\Lib\site-packages\urllib3\util\connection.py", line 85, in create_connection    raise err  File "D:\Program Files\Python\Python311\Lib\site-packages\urllib3\util\connection.py", line 73, in create_connection    sock.connect(sa)ConnectionRefusedError: [WinError 10061] ����Ŀ�����������ܾ����޷����ӡ�The above exception was the direct cause of the following exception:Traceback (most recent call last):  File "D:\Program Files\Python\Python311\Lib\site-packages\urllib3\connectionpool.py", line 775, in urlopen    self._prepare_proxy(conn)  File "D:\Program Files\Python\Python311\Lib\site-packages\urllib3\connectionpool.py", line 1044, in _prepare_proxy    conn.connect()  File "D:\Program Files\Python\Python311\Lib\site-packages\urllib3\connection.py", line 693, in connect    self.sock = sock = self._new_conn()                       ^^^^^^^^^^^^^^^^  File "D:\Program Files\Python\Python311\Lib\site-packages\urllib3\connection.py", line 214, in _new_conn    raise NewConnectionError(urllib3.exceptions.NewConnectionError: <urllib3.connection.HTTPSConnection object at 0x000001567FB6AC10>: Failed to establish a new connection: [WinError 10061] ����Ŀ�����������ܾ����޷����ӡ�The above exception was the direct cause of the following exception:urllib3.exceptions.ProxyError: ('Unable to connect to proxy', NewConnectionError('<urllib3.connection.HTTPSConnection object at 0x000001567FB6AC10>: Failed to establish a new connection: [WinError 10061] ����Ŀ�����������ܾ����޷����ӡ�'))The above exception was the direct cause of the following exception:Traceback (most recent call last):  File "D:\Program Files\Python\Python311\Lib\site-packages\requests\adapters.py", line 667, in send    resp = conn.urlopen(           ^^^^^^^^^^^^^  File "D:\Program Files\Python\Python311\Lib\site-packages\urllib3\connectionpool.py", line 843, in urlopen    retries = retries.increment(              ^^^^^^^^^^^^^^^^^^  File "D:\Program Files\Python\Python311\Lib\site-packages\urllib3\util\retry.py", line 519, in increment    raise MaxRetryError(_pool, url, reason) from reason  # type: ignore[arg-type]    ^^^^^^^^^^^^^^^^^^^^^^^^^^^^^^^^^^^^^^^^^^^^^^^^^^^urllib3.exceptions.MaxRetryError: HTTPSConnectionPool(host='huggingface.co', port=443): Max retries exceeded with url: /bert-base-chinese/resolve/main/tokenizer_config.json (Caused by ProxyError('Unable to connect to proxy', NewConnectionError('<urllib3.connection.HTTPSConnection object at 0x000001567FB6AC10>: Failed to establish a new connection: [WinError 10061] ����Ŀ�����������ܾ����޷����ӡ�')))During handling of the above exception, another exception occurred:Traceback (most recent call last):  File "D:\Codes\Java\SpringBoot\demo\src\main\resources\python\milvus_search.py", line 91, in <module>    main()  File "D:\Codes\Java\SpringBoot\demo\src\main\resources\python\milvus_search.py", line 59, in main    tokenizer, model, collection = initialize_milvus()                                   ^^^^^^^^^^^^^^^^^^^  File "D:\Codes\Java\SpringBoot\demo\src\main\resources\python\milvus_search.py", line 13, in initialize_milvus    tokenizer = BertTokenizer.from_pretrained('bert-base-chinese')                ^^^^^^^^^^^^^^^^^^^^^^^^^^^^^^^^^^^^^^^^^^^^^^^^^^  File "D:\Program Files\Python\Python311\Lib\site-packages\transformers\tokenization_utils_base.py", line 1951, in from_pretrained    resolved_config_file = cached_file(                           ^^^^^^^^^^^^  File "D:\Program Files\Python\Python311\Lib\site-packages\transformers\utils\hub.py", line 403, in cached_file    resolved_file = hf_hub_download(                    ^^^^^^^^^^^^^^^^  File "D:\Program Files\Python\Python311\Lib\site-packages\huggingface_hub\utils\_validators.py", line 114, in _inner_fn    return fn(*args, **kwargs)           ^^^^^^^^^^^^^^^^^^^  File "D:\Program Files\Python\Python311\Lib\site-packages\huggingface_hub\file_download.py", line 860, in hf_hub_download    return _hf_hub_download_to_cache_dir(           ^^^^^^^^^^^^^^^^^^^^^^^^^^^^^^  File "D:\Program Files\Python\Python311\Lib\site-packages\huggingface_hub\file_download.py", line 923, in _hf_hub_download_to_cache_dir    (url_to_download, etag, commit_hash, expected_size, head_call_error) = _get_metadata_or_catch_error(                                                                           ^^^^^^^^^^^^^^^^^^^^^^^^^^^^^  File "D:\Program Files\Python\Python311\Lib\site-packages\huggingface_hub\file_download.py", line 1374, in _get_metadata_or_catch_error    metadata = get_hf_file_metadata(               ^^^^^^^^^^^^^^^^^^^^^  File "D:\Program Files\Python\Python311\Lib\site-packages\huggingface_hub\utils\_validators.py", line 114, in _inner_fn    return fn(*args, **kwargs)           ^^^^^^^^^^^^^^^^^^^  File "D:\Program Files\Python\Python311\Lib\site-packages\huggingface_hub\file_download.py", line 1294, in get_hf_file_metadata    r = _request_wrapper(        ^^^^^^^^^^^^^^^^^  File "D:\Program Files\Python\Python311\Lib\site-packages\huggingface_hub\file_download.py", line 278, in _request_wrapper    response = _request_wrapper(               ^^^^^^^^^^^^^^^^^  File "D:\Program Files\Python\Python311\Lib\site-packages\huggingface_hub\file_download.py", line 301, in _request_wrapper    response = get_session().request(method=method, url=url, **params)               ^^^^^^^^^^^^^^^^^^^^^^^^^^^^^^^^^^^^^^^^^^^^^^^^^^^^^^^  File "D:\Program Files\Python\Python311\Lib\site-packages\requests\sessions.py", line 589, in request    resp = self.send(prep, **send_kwargs)           ^^^^^^^^^^^^^^^^^^^^^^^^^^^^^^  File "D:\Program Files\Python\Python311\Lib\site-packages\requests\sessions.py", line 703, in send    r = adapter.send(request, **kwargs)        ^^^^^^^^^^^^^^^^^^^^^^^^^^^^^^^  File "D:\Program Files\Python\Python311\Lib\site-packages\huggingface_hub\utils\_http.py", line 93, in send    return super().send(request, *args, **kwargs)           ^^^^^^^^^^^^^^^^^^^^^^^^^^^^^^^^^^^^^^  File "D:\Program Files\Python\Python311\Lib\site-packages\requests\adapters.py", line 694, in send    raise ProxyError(e, request=request)requests.exceptions.ProxyError: (MaxRetryError("HTTPSConnectionPool(host='huggingface.co', port=443): Max retries exceeded with url: /bert-base-chinese/resolve/main/tokenizer_config.json (Caused by ProxyError('Unable to connect to proxy', NewConnectionError('<urllib3.connection.HTTPSConnection object at 0x000001567FB6AC10>: Failed to establish a new connection: [WinError 10061] ����Ŀ�����������ܾ����޷����ӡ�')))"), '(Request ID: 28b91802-ea87-4d34-8655-6d0bdb26fbf1)')
 @$@